<?xml version="1.0"?>

<!--Name of robot-->
<robot xmlns:xacro="http://www.ros.org/wiki/xacro" name="Roberto_MkI">

  <!--Naming Materials-->
  <material name="blue">
    <color rgba="0 0 0.8 1"/>
  </material>

  <material name="white">
    <color rgba="1 1 1 1"/>
  </material>

  <!--Xacro Macros-->
  <!--Body Macros-->
  <xacro:property name="body_size" value="1.0 0.6 0.3" />

  <!--Wheel Macros-->
  <xacro:property name="wheel_len" value=".15" />
  <xacro:property name="wheel_rad" value=".2" />
  <xacro:property name="wheel_origin" value="1.57075 0 0" />
  <xacro:macro name="wheel" params="suffix reflect_x reflect_y reflect_z">
    <link name="link_${suffix}">
      <visual>
        <geometry>
          <cylinder length="${wheel_len}" radius="${wheel_rad}"/>
        </geometry>
        <origin rpy="${wheel_origin}"/>
        <material name="blue"/>
      </visual>
      <collision>
        <geometry>
          <cylinder length="${wheel_len}" radius="${wheel_rad}"/>
        </geometry>
        <origin rpy="${wheel_origin}"/>
      </collision>
      <inertial>
        <mass value="12.01"/>
        <inertia ixx=".14" ixy="0" ixz="0" iyy="0.24" iyz="0" izz=".14"/>
      </inertial>
    </link>

    <joint name="wheel_joint_${suffix}" type="continuous">
      <parent link="base_link"/>
      <child link="link_${suffix}"/>
      <axis xyz="0 1 0"/>
      <origin rpy="0 0 0" xyz="${reflect_x * 0.3} ${reflect_y * 0.375} ${reflect_z * 0.075}"/>
    </joint>
    
    <!--Connects Gazebo to ROS Controls-->
    <transmission name="joint_${suffix}_wheel_trans">
      <type>transmission_interface/SimpleTransmission</type>
      <actuator name="joint_${suffix}_wheel_motor">
        <mechanicalReduction>1</mechanicalReduction>
      </actuator>
      <joint name="joint_${suffix}">
        <hardwareInterface>hardware_interface/VelocityJointInterface</hardwareInterface>
      </joint>
    </transmission>
    
    <!--Some extra Gazebo details-->
    <gazebo reference="link_${suffix}">
      <mu1 value="200.0"/>
      <mu2 value="100.0"/>
      <kp value="10000000.0" />
      <kd value="1.0" />
      <material>Gazebo/Blue</material>
    </gazebo>
    
  </xacro:macro>

  <!--Links-->
  <!--Body(base_link)-->
  <link name="base_link">
    <!--Visual-->
    <visual>
      <geometry>
        <box size="${body_size}"/>
      </geometry>
        <material name="white"/>
    </visual>
    <!--Collision-->
    <collision>
      <geometry>
        <box size="${body_size}"/>
      </geometry>
    </collision>
    <inertial>
      <mass value="108.09"/>
      <!--inertia: required by Gazebo-->  
      <!--6 values: ixx ixy ixz iyy iyz izz-->
      <inertia ixx="4.05" ixy="0" ixz="0" iyy="9.82" iyz="0" izz="12.25"/>
    </inertial>
    <gazebo>
      <material>Gazebo/Grey</material>
    </gazebo>
  </link>

  <!--wheel/joint_0-->
  <xacro:wheel suffix="0" reflect_x="1" reflect_y="1" reflect_z="-1" />
  <!--wheel/joint_1-->
  <xacro:wheel suffix="1" reflect_x="1" reflect_y="-1" reflect_z="-1" />
  <!--wheel/joint_2-->
  <xacro:wheel suffix="2" reflect_x="-1" reflect_y="1" reflect_z="-1" />
  <!--wheel/joint_3-->
  <xacro:wheel suffix="3" reflect_x="-1" reflect_y="-1" reflect_z="-1" />

  <!--<link name="auger">
    <visual>
      <origin rpy="0 0 0" xyz="0 0 0"/>
      <geometry>
         <mesh filename="package://lunarbot/meshes/auger.dae"/>
      </geometry>
    </visual>
  </link>
  <collision>
    <geometry>
      <cylinder length="1.3" radius=".2"/>
    </geometry>
  </collision>
  <inertial>
    <mass value="33"/>
    <inertia ixx="4.73" ixy="0" ixz="0" iyy="4.73" iyz="0" izz=".165"/>
  </inertial>
  
  <joint name="auger" type="continuous">
    <parent link="base_link"/>
    <child link="auger"/>
    <axis xyz="0 0 1"/>
    <origin rpy="0 0 0" xyz="0 0 1"/>
  </joint>-->

	<!--Gazebo plugin for ROS controls-->
	<gazebo>
		<plugin name="gazebo_ros_control" filename="libgazebo_ros_control.so">
			<robotNamespace>/</robotNamespace>
		</plugin>
	</gazebo>

</robot>
